Workbook
Name Slicer_Age_Bracket: #N/A
Name Slicer_Region: #N/A

Sheet Customer
A1: CustomerID | B1: Name | C1: Gender | D1: Age | E1: Age Bracket | F1: Region | G1: Occupation | H1: Income | I1: Income Segment | J1: Customer_Segment | K1: Join_Date | L1: Year | M1: Customer Duration
A2: CUST0001 | B2: Mrs. Deborah Dominguez MD | C2: Male | D2: 38 | E2: Millennials | F2: North | G2: Doctor | H2: 191672 | I2: High | J2: Retail | K2: 45041 | L2: 2023 | M2: 1203 days
A3: CUST0002 | B3: Erin Martinez | C3: Female | D3: 49 | E3: Gen X | F3: East | G3: Trader | H3: 186472 | I3: High | J3: Corporate | K3: 44331 | L3: 2021 | M3: 1913 days
A4: CUST0003 | B4: Amanda Harris | C4: Male | D4: 40 | E4: Millennials | F4: North | G4: Teacher | H4: 155566 | I4: High | J4: Private | K4: 43438 | L4: 2018 | M4: 2806 days
A5: CUST0004 | B5: Candice Palmer | C5: Male | D5: 50 | E5: Gen X | F5: North | G5: Banker | H5: 142744 | I5: High | J5: Retail | K5: 44494 | L5: 2021 | M5: 1750 days
A6: CUST0005 | B6: Sandra Davis | C6: Male | D6: 20 | E6: Gen z | F6: West | G6: Student | H6: 109431 | I6: Medium | J6: Corporate | K6: 43309 | L6: 2018 | M6: 2935 days | S6: Checking | T6: Savings | U6: Loan | V6: Credit Card
A7: CUST0006 | B7: Vanessa Peterson | C7: Female | D7: 35 | E7: Millennials | F7: South | G7: Teacher | H7: 63001 | I7: Low | J7: Retail | K7: 42520 | L7: 2016 | M7: 3724 days | R7: Most Common account type | S7: =COUNTIF(Linked[Account Type],"Checking") -> 246 | T7: =COUNTIF(Linked[Account Type],"Savings") -> 303 | U7: =COUNTIF(Linked[Account Type],"Loan") -> 82 | V7: =COUNTIF(Linked[Account Type],"CreditCard") -> 169
A8: CUST0007 | B8: Tyler Fischer | C8: Male | D8: 42 | E8: Millennials | F8: North | G8: Engineer | H8: 87364 | I8: Medium | J8: Corporate | K8: 43026 | L8: 2017 | M8: 3218 days | R8: Count of Customers with multiple accounts
A9: CUST0008 | B9: William Horton | C9: Male | D9: 59 | E9: Gen X | F9: North | G9: Engineer | H9: 144988 | I9: High | J9: Retail | K9: 45448 | L9: 2024 | M9: 796 days | R9: Total amount of Approved Loans | S9: =SUMIF(Linked[Loan Status],"Approved",Linked[Loan Amount]) -> 3677399
A10: CUST0009 | B10: Donna Williams | C10: Male | D10: 48 | E10: Gen X | F10: West | G10: Retired | H10: 65028 | I10: Low | J10: Corporate | K10: 43507 | L10: 2019 | M10: 2737 days | S10: Retail | T10: Private | U10: Corporate
A11: CUST0010 | B11: Mary Casey | C11: Female | D11: 71 | E11: Boomers | F11: West | G11: Trader | H11: 188645 | I11: High | J11: Corporate | K11: 42405 | L11: 2016 | M11: 3839 days | R11: Highest Average Balance | S11: =AVERAGEIF(Linked[Customer Segment],"Retail",Linked[Balance]) -> 267102.03 | T11: =AVERAGEIF(Linked[Customer Segment],"Private",Linked[Balance]) -> 275113.66 | U11: =AVERAGEIF(Linked[Customer Segment],"Corporate",Linked[Balance]) -> 259460.32
A12: CUST0011 | B12: Kevin Phillips | C12: Male | D12: 20 | E12: Gen z | F12: South | G12: Doctor | H12: 151878 | I12: High | J12: Private | K12: 42781 | L12: 2017 | M12: 3463 days | R12: Average Balance | S12: =AVERAGE(Linked[Balance]) -> 265426.42
A13: CUST0012 | B13: Michael Richard | C13: Male | D13: 57 | E13: Gen X | F13: West | G13: Trader | H13: 144343 | I13: High | J13: Corporate | K13: 45280 | L13: 2023 | M13: 964 days | R13: Total Loan Amount | S13: =SUM(Linked[Loan Amount]) -> 43730664
A14: CUST0013 | B14: Jaime Davis MD | C14: Male | D14: 63 | E14: Boomers | F14: East | G14: Trader | H14: 148301 | I14: High | J14: Retail | K14: 45018 | L14: 2023 | M14: 1226 days | R14: Total Deposit Balance | S14: =SUMIF(Linked[Account Type],"Checking",Linked[Balance])+SUMIF(Linked[Account Type],"Savings",Linked[Balance]) -> 145013181
A15: CUST0014 | B15: Eric Peterson | C15: Male | D15: 41 | E15: Millennials | F15: West | G15: Trader | H15: 146295 | I15: High | J15: Corporate | K15: 42960 | L15: 2017 | M15: 3284 days | R15: Average Credit Score | S15: =AVERAGE(Linked[Credit Score]) -> 579.52625 | T15: =IF(S15<=579,"Poor",IF(S15<=669,"Fair",IF(S15<=739,"Good",IF(S15<=799,"Very Good",IF(S15>=800,"Excellent"))))) -> Fair
A16: CUST0015 | B16: Ms. Renee Cardenas PhD | C16: Female | D16: 67 | E16: Boomers | F16: East | G16: Trader | H16: 180829 | I16: High | J16: Corporate | K16: 43673 | L16: 2019 | M16: 2571 days | R16: No of Approved Loans
A17: CUST0016 | B17: Ashlee Baird | C17: Male | D17: 49 | E17: Gen X | F17: South | G17: Banker | H17: 54636 | I17: Low | J17: Retail | K17: 43643 | L17: 2019 | M17: 2601 days | R17: Checking Average credit score | S17: =AVERAGEIF(Linked[Account Type],"Checking",Linked[Credit Score]) -> 578.67073 | T17: =IF(S17<=579,"Poor",IF(S17<=669,"Fair",IF(S17<=739,"Good",IF(S17<=799,"Very Good",IF(S17>=800,"Excellent"))))) -> Poor
A18: CUST0017 | B18: Michael Conner | C18: Female | D18: 64 | E18: Boomers | F18: South | G18: Banker | H18: 199352 | I18: High | J18: Retail | K18: 44375 | L18: 2021 | M18: 1869 days | R18: Savings Average credit score | S18: =AVERAGEIF(Linked[Account Type],"Savings",Linked[Credit Score]) -> 586.9868 | T18: =IF(S18<=579,"Poor",IF(S18<=669,"Fair",IF(S18<=739,"Good",IF(S18<=799,"Very Good",IF(S18>=800,"Excellent"))))) -> Fair
A19: CUST0018 | B19: Jeff Koch | C19: Female | D19: 39 | E19: Millennials | F19: South | G19: Retired | H19: 44262 | I19: Low | J19: Private | K19: 45728 | L19: 2025 | M19: 516 days | R19: Loan Average credit score | S19: =AVERAGEIF(Linked[Account Type],"Loan",Linked[Credit Score]) -> 564 | T19: =IF(S19<=579,"Poor",IF(S19<=669,"Fair",IF(S19<=739,"Good",IF(S19<=799,"Very Good",IF(S19>=800,"Excellent"))))) -> Poor
A20: CUST0019 | B20: Melissa Clark | C20: Female | D20: 40 | E20: Millennials | F20: South | G20: Teacher | H20: 100435 | I20: Medium | J20: Corporate | K20: 44456 | L20: 2021 | M20: 1788 days | R20: CrediT Card Average credit score | S20: =AVERAGEIF(Linked[Account Type],"CreditCard",Linked[Credit Score]) -> 574.92899 | T20: =IF(S20<=579,"Poor",IF(S20<=669,"Fair",IF(S20<=739,"Good",IF(S20<=799,"Very Good",IF(S20>=800,"Excellent"))))) -> Poor
A21: CUST0020 | B21: Janice Scott | C21: Male | D21: 19 | E21: Gen z | F21: South | G21: Engineer | H21: 148583 | I21: High | J21: Corporate | K21: 45058 | L21: 2023 | M21: 1186 days | R21: AVG credit score of approved loans | S21: =GETPIVOTDATA("Credit Score",'Pivot Table'!$H$22,"Loan Status","Approved") -> 580.50877
A22: CUST0021 | B22: Elizabeth Smith | C22: Female | D22: 44 | E22: Millennials | F22: East | G22: Trader | H22: 189269 | I22: High | J22: Retail | K22: 45414 | L22: 2024 | M22: 830 days | R22: AVG credit score of Rejected loans | S22: =GETPIVOTDATA("Credit Score",'Pivot Table'!$H$22,"Loan Status","Rejected") -> 591.81159
A23: CUST0022 | B23: Jodi Burns | C23: Male | D23: 59 | E23: Gen X | F23: East | G23: Retired | H23: 61844 | I23: Low | J23: Corporate | K23: 45118 | L23: 2023 | M23: 1126 days | R23: Total Value of approved loans | S23: =SUMIF(Linked[Loan Status],"Approved",Linked[Loan Amount]) -> 3677399
A24: CUST0023 | B24: Robert Robertson | C24: Female | D24: 19 | E24: Gen z | F24: South | G24: Teacher | H24: 84754 | I24: Medium | J24: Retail | K24: 44745 | L24: 2022 | M24: 1499 days | R24: Total Balance | S24: =SUM(Linked[Balance]) -> 212341134
A25: CUST0024 | B25: Curtis Scott | C25: Female | D25: 43 | E25: Millennials | F25: West | G25: Engineer | H25: 185229 | I25: High | J25: Corporate | K25: 42765 | L25: 2017 | M25: 3479 days
A26: CUST0025 | B26: Cindy Parks | C26: Female | D26: 34 | E26: Millennials | F26: North | G26: Student | H26: 97129 | I26: Medium | J26: Retail | K26: 43718 | L26: 2019 | M26: 2526 days
A27: CUST0026 | B27: Charles Fields | C27: Female | D27: 57 | E27: Gen X | F27: South | G27: Doctor | H27: 60042 | I27: Low | J27: Corporate | K27: 44469 | L27: 2021 | M27: 1775 days
A28: CUST0027 | B28: Michael Murray MD | C28: Female | D28: 50 | E28: Gen X | F28: West | G28: Banker | H28: 81665 | I28: Medium | J28: Private | K28: 42607 | L28: 2016 | M28: 3637 days
A29: CUST0028 | B29: Edward Haynes | C29: Female | D29: 26 | E29: Gen z | F29: North | G29: Student | H29: 136953 | I29: Medium | J29: Retail | K29: 43698 | L29: 2019 | M29: 2546 days
A30: CUST0029 | B30: James Allen | C30: Female | D30: 60 | E30: Gen X | F30: South | G30: Engineer | H30: 178448 | I30: High | J30: Private | K30: 44834 | L30: 2022 | M30: 1410 days
A31: CUST0030 | B31: Angela Robinson | C31: Female | D31: 71 | E31: Boomers | F31: South | G31: Student | H31: 165271 | I31: High | J31: Retail | K31: 44109 | L31: 2020 | M31: 2135 days
A32: CUST0031 | B32: Michelle Day | C32: Male | D32: 65 | E32: Boomers | F32: East | G32: Doctor | H32: 138533 | I32: Medium | J32: Corporate | K32: 42742 | L32: 2017 | M32: 3502 days
A33: CUST0032 | B33: Steven Walker | C33: Male | D33: 56 | E33: Gen X | F33: North | G33: Retired | H33: 93781 | I33: Medium | J33: Corporate | K33: 42565 | L33: 2016 | M33: 3679 days
A34: CUST0033 | B34: Lindsey Christensen | C34: Female | D34: 46 | E34: Gen X | F34: North | G34: Engineer | H34: 86262 | I34: Medium | J34: Retail | K34: 43698 | L34: 2019 | M34: 2546 days
A35: CUST0034 | B35: Brooke Carlson | C35: Female | D35: 59 | E35: Gen X | F35: West | G35: Student | H35: 66600 | I35: Low | J35: Corporate | K35: 44513 | L35: 2021 | M35: 1731 days
A36: CUST0035 | B36: Kevin Marshall | C36: Female | D36: 72 | E36: Boomers | F36: East | G36: Banker | H36: 96898 | I36: Medium | J36: Corporate | K36: 42533 | L36: 2016 | M36: 3711 days
... A501: CUST0500 | B501: Olivia Barton | C501: Female | D501: 63 | E501: Boomers | F501: South | G501: Student | H501: 21969 | I501: Low | J501: Corporate | K501: 45488 | L501: 2024 | M501: 756 days

Sheet Customers Account
A1: CustomerID | B1: AccountID | C1: Name | D1: Gender | E1: Age | F1: Age Bracket | G1: Region | H1: Occupation | I1: Join Date | J1: Join Year | K1: Customer Duration | L1: Income | M1: Income Segment | N1: Customer Segment | O1: Account Type | P1: Open Date | Q1: Balance | R1: Credit Score | S1: Credit Score Bracket | T1: Loan Amount | U1: Loan Status
A2: CUST0305 | B2: ACC00001 | C2: Erica Perez | D2: Female | E2: 46 | F2: Gen X | G2: West | H2: Trader | I2: 43041 | J2: 2017 | K2: 3203 days | L2: 29078 | M2: Low | N2: Corporate | O2: Checking | P2: 43258 | Q2: 363265 | R2: 698 | S2: =IF(Linked[[#This Row],[Credit Score]]<=579,"Poor",IF(Linked[[#This Row],[Credit Score]]<=669,"Fair",IF(Linked[[#This Row],[Credit Score]]<=739,"Good",IF(Linked[[#This Row],[Credit Score]]<=799,"Very Good",IF(Linked[[#This Row],[Credit Score]]>=800,"Excellent"))))) -> Good | T2: 0
A3: CUST0305 | B3: ACC00185 | C3: Erica Perez | D3: Female | E3: 46 | F3: Gen X | G3: West | H3: Trader | I3: 43041 | J3: 2017 | K3: 3203 days | L3: 29078 | M3: Low | N3: Corporate | O3: Savings | P3: 44094 | Q3: 398834 | R3: 304 | S3: =IF(Linked[[#This Row],[Credit Score]]<=579,"Poor",IF(Linked[[#This Row],[Credit Score]]<=669,"Fair",IF(Linked[[#This Row],[Credit Score]]<=739,"Good",IF(Linked[[#This Row],[Credit Score]]<=799,"Very Good",IF(Linked[[#This Row],[Credit Score]]>=800,"Excellent"))))) -> Poor | T3: 0
A4: CUST0001 | B4: ACC00461 | C4: Mrs. Deborah Dominguez MD | D4: Male | E4: 38 | F4: Millennials | G4: North | H4: Doctor | I4: 45041 | J4: 2023 | K4: 1203 days | L4: 191672 | M4: High | N4: Retail | O4: Savings | P4: 45360 | Q4: 370180 | R4: 344 | S4: =IF(Linked[[#This Row],[Credit Score]]<=579,"Poor",IF(Linked[[#This Row],[Credit Score]]<=669,"Fair",IF(Linked[[#This Row],[Credit Score]]<=739,"Good",IF(Linked[[#This Row],[Credit Score]]<=799,"Very Good",IF(Linked[[#This Row],[Credit Score]]>=800,"Excellent"))))) -> Poor | T4: 0
A5: CUST0319 | B5: ACC00002 | C5: Reginald Tapia | D5: Male | E5: 57 | F5: Gen X | G5: East | H5: Retired | I5: 43637 | J5: 2019 | K5: 2607 days | L5: 122215 | M5: Medium | N5: Private | O5: Savings | P5: 45670 | Q5: 282169 | R5: 405 | S5: =IF(Linked[[#This Row],[Credit Score]]<=579,"Poor",IF(Linked[[#This Row],[Credit Score]]<=669,"Fair",IF(Linked[[#This Row],[Credit Score]]<=739,"Good",IF(Linked[[#This Row],[Credit Score]]<=799,"Very Good",IF(Linked[[#This Row],[Credit Score]]>=800,"Excellent"))))) -> Poor | T5: 0
A6: CUST0319 | B6: ACC00026 | C6: Reginald Tapia | D6: Male | E6: 57 | F6: Gen X | G6: East | H6: Retired | I6: 43637 | J6: 2019 | K6: 2607 days | L6: 122215 | M6: Medium | N6: Private | O6: Savings | P6: 43851 | Q6: 97493 | R6: 528 | S6: =IF(Linked[[#This Row],[Credit Score]]<=579,"Poor",IF(Linked[[#This Row],[Credit Score]]<=669,"Fair",IF(Linked[[#This Row],[Credit Score]]<=739,"Good",IF(Linked[[#This Row],[Credit Score]]<=799,"Very Good",IF(Linked[[#This Row],[Credit Score]]>=800,"Excellent"))))) -> Poor | T6: 0
A7: CUST0319 | B7: ACC00249 | C7: Reginald Tapia | D7: Male | E7: 57 | F7: Gen X | G7: East | H7: Retired | I7: 43637 | J7: 2019 | K7: 2607 days | L7: 122215 | M7: Medium | N7: Private | O7: Savings | P7: 42662 | Q7: 357574 | R7: 546 | S7: =IF(Linked[[#This Row],[Credit Score]]<=579,"Poor",IF(Linked[[#This Row],[Credit Score]]<=669,"Fair",IF(Linked[[#This Row],[Credit Score]]<=739,"Good",IF(Linked[[#This Row],[Credit Score]]<=799,"Very Good",IF(Linked[[#This Row],[Credit Score]]>=800,"Excellent"))))) -> Poor | T7: 0 | U7: Approved
A8: CUST0002 | B8: ACC00225 | C8: Erin Martinez | D8: Female | E8: 49 | F8: Gen X | G8: East | H8: Trader | I8: 44331 | J8: 2021 | K8: 1913 days | L8: 186472 | M8: High | N8: Corporate | O8: CreditCard | P8: 44739 | Q8: 40142 | R8: 541 | S8: =IF(Linked[[#This Row],[Credit Score]]<=579,"Poor",IF(Linked[[#This Row],[Credit Score]]<=669,"Fair",IF(Linked[[#This Row],[Credit Score]]<=739,"Good",IF(Linked[[#This Row],[Credit Score]]<=799,"Very Good",IF(Linked[[#This Row],[Credit Score]]>=800,"Excellent"))))) -> Poor | T8: 0 | U8: Default
A9: CUST0366 | B9: ACC00003 | C9: Gregory Lee | D9: Male | E9: 45 | F9: Gen X | G9: East | H9: Trader | I9: 43773 | J9: 2019 | K9: 2471 days | L9: 36309 | M9: Low | N9: Retail | O9: Savings | P9: 43852 | Q9: 397674 | R9: 570 | S9: =IF(Linked[[#This Row],[Credit Score]]<=579,"Poor",IF(Linked[[#This Row],[Credit Score]]<=669,"Fair",IF(Linked[[#This Row],[Credit Score]]<=739,"Good",IF(Linked[[#This Row],[Credit Score]]<=799,"Very Good",IF(Linked[[#This Row],[Credit Score]]>=800,"Excellent"))))) -> Poor | T9: 0
A10: CUST0366 | B10: ACC00259 | C10: Gregory Lee | D10: Male | E10: 45 | F10: Gen X | G10: East | H10: Trader | I10: 43773 | J10: 2019 | K10: 2471 days | L10: 36309 | M10: Low | N10: Retail | O10: Checking | P10: 45597 | Q10: 266378 | R10: 634 | S10: =IF(Linked[[#This Row],[Credit Score]]<=579,"Poor",IF(Linked[[#This Row],[Credit Score]]<=669,"Fair",IF(Linked[[#This Row],[Credit Score]]<=739,"Good",IF(Linked[[#This Row],[Credit Score]]<=799,"Very Good",IF(Linked[[#This Row],[Credit Score]]>=800,"Excellent"))))) -> Fair | T10: 0
A11: CUST0366 | B11: ACC00350 | C11: Gregory Lee | D11: Male | E11: 45 | F11: Gen X | G11: East | H11: Trader | I11: 43773 | J11: 2019 | K11: 2471 days | L11: 36309 | M11: Low | N11: Retail | O11: Savings | P11: 43800 | Q11: 282140 | R11: 756 | S11: =IF(Linked[[#This Row],[Credit Score]]<=579,"Poor",IF(Linked[[#This Row],[Credit Score]]<=669,"Fair",IF(Linked[[#This Row],[Credit Score]]<=739,"Good",IF(Linked[[#This Row],[Credit Score]]<=799,"Very Good",IF(Linked[[#This Row],[Credit Score]]>=800,"Excellent"))))) -> Very Good | T11: 0 | U11: Approved
A12: CUST0211 | B12: ACC00004 | C12: Ryan Mccormick | D12: Male | E12: 34 | F12: Millennials | G12: North | H12: Doctor | I12: 43881 | J12: 2020 | K12: 2363 days | L12: 148386 | M12: High | N12: Corporate | O12: Savings | P12: 44837 | Q12: 63610 | R12: 802 | S12: =IF(Linked[[#This Row],[Credit Score]]<=579,"Poor",IF(Linked[[#This Row],[Credit Score]]<=669,"Fair",IF(Linked[[#This Row],[Credit Score]]<=739,"Good",IF(Linked[[#This Row],[Credit Score]]<=799,"Very Good",IF(Linked[[#This Row],[Credit Score]]>=800,"Excellent"))))) -> Excellent | T12: 401875 | U12: Rejected
A13: CUST0211 | B13: ACC00396 | C13: Ryan Mccormick | D13: Male | E13: 34 | F13: Millennials | G13: North | H13: Doctor | I13: 43881 | J13: 2020 | K13: 2363 days | L13: 148386 | M13: High | N13: Corporate | O13: CreditCard | P13: 45320 | Q13: 232654 | R13: 633 | S13: =IF(Linked[[#This Row],[Credit Score]]<=579,"Poor",IF(Linked[[#This Row],[Credit Score]]<=669,"Fair",IF(Linked[[#This Row],[Credit Score]]<=739,"Good",IF(Linked[[#This Row],[Credit Score]]<=799,"Very Good",IF(Linked[[#This Row],[Credit Score]]>=800,"Excellent"))))) -> Fair | T13: 0
A14: CUST0004 | B14: ACC00468 | C14: Candice Palmer | D14: Male | E14: 50 | F14: Gen X | G14: North | H14: Banker | I14: 44494 | J14: 2021 | K14: 1750 days | L14: 142744 | M14: High | N14: Retail | O14: Checking | P14: 42867 | Q14: 128216 | R14: 849 | S14: =IF(Linked[[#This Row],[Credit Score]]<=579,"Poor",IF(Linked[[#This Row],[Credit Score]]<=669,"Fair",IF(Linked[[#This Row],[Credit Score]]<=739,"Good",IF(Linked[[#This Row],[Credit Score]]<=799,"Very Good",IF(Linked[[#This Row],[Credit Score]]>=800,"Excellent"))))) -> Excellent | T14: 0
A15: CUST0406 | B15: ACC00005 | C15: Katherine Freeman | D15: Female | E15: 28 | F15: Gen z | G15: East | H15: Retired | I15: 44902 | J15: 2022 | K15: 1342 days | L15: 39975 | M15: Low | N15: Corporate | O15: Savings | P15: 44039 | Q15: 70843 | R15: 824 | S15: =IF(Linked[[#This Row],[Credit Score]]<=579,"Poor",IF(Linked[[#This Row],[Credit Score]]<=669,"Fair",IF(Linked[[#This Row],[Credit Score]]<=739,"Good",IF(Linked[[#This Row],[Credit Score]]<=799,"Very Good",IF(Linked[[#This Row],[Credit Score]]>=800,"Excellent"))))) -> Excellent | T15: 458505
A16: CUST0005 | B16: ACC00224 | C16: Sandra Davis | D16: Male | E16: 20 | F16: Gen z | G16: West | H16: Student | I16: 43309 | J16: 2018 | K16: 2935 days | L16: 109431 | M16: Medium | N16: Corporate | O16: Checking | P16: 42503 | Q16: 163202 | R16: 491 | S16: =IF(Linked[[#This Row],[Credit Score]]<=579,"Poor",IF(Linked[[#This Row],[Credit Score]]<=669,"Fair",IF(Linked[[#This Row],[Credit Score]]<=739,"Good",IF(Linked[[#This Row],[Credit Score]]<=799,"Very Good",IF(Linked[[#This Row],[Credit Score]]>=800,"Excellent"))))) -> Poor | T16: 0
A17: CUST0152 | B17: ACC00006 | C17: Eric Gomez | D17: Male | E17: 38 | F17: Millennials | G17: East | H17: Retired | I17: 43409 | J17: 2018 | K17: 2835 days | L17: 177732 | M17: High | N17: Corporate | O17: Checking | P17: 44185 | Q17: 107237 | R17: 331 | S17: =IF(Linked[[#This Row],[Credit Score]]<=579,"Poor",IF(Linked[[#This Row],[Credit Score]]<=669,"Fair",IF(Linked[[#This Row],[Credit Score]]<=739,"Good",IF(Linked[[#This Row],[Credit Score]]<=799,"Very Good",IF(Linked[[#This Row],[Credit Score]]>=800,"Excellent"))))) -> Poor | T17: 163666
A18: CUST0152 | B18: ACC00112 | C18: Eric Gomez | D18: Male | E18: 38 | F18: Millennials | G18: East | H18: Retired | I18: 43409 | J18: 2018 | K18: 2835 days | L18: 177732 | M18: High | N18: Corporate | O18: CreditCard | P18: 43077 | Q18: 375197 | R18: 567 | S18: =IF(Linked[[#This Row],[Credit Score]]<=579,"Poor",IF(Linked[[#This Row],[Credit Score]]<=669,"Fair",IF(Linked[[#This Row],[Credit Score]]<=739,"Good",IF(Linked[[#This Row],[Credit Score]]<=799,"Very Good",IF(Linked[[#This Row],[Credit Score]]>=800,"Excellent"))))) -> Poor | T18: 0
A19: CUST0152 | B19: ACC00204 | C19: Eric Gomez | D19: Male | E19: 38 | F19: Millennials | G19: East | H19: Retired | I19: 43409 | J19: 2018 | K19: 2835 days | L19: 177732 | M19: High | N19: Corporate | O19: Checking | P19: 45602 | Q19: 333840 | R19: 428 | S19: =IF(Linked[[#This Row],[Credit Score]]<=579,"Poor",IF(Linked[[#This Row],[Credit Score]]<=669,"Fair",IF(Linked[[#This Row],[Credit Score]]<=739,"Good",IF(Linked[[#This Row],[Credit Score]]<=799,"Very Good",IF(Linked[[#This Row],[Credit Score]]>=800,"Excellent"))))) -> Poor | T19: 0
A20: CUST0109 | B20: ACC00007 | C20: Emily Scott | D20: Female | E20: 29 | F20: Millennials | G20: North | H20: Engineer | I20: 44077 | J20: 2020 | K20: 2167 days | L20: 131785 | M20: Medium | N20: Corporate | O20: CreditCard | P20: 44160 | Q20: 477177 | R20: 692 | S20: =IF(Linked[[#This Row],[Credit Score]]<=579,"Poor",IF(Linked[[#This Row],[Credit Score]]<=669,"Fair",IF(Linked[[#This Row],[Credit Score]]<=739,"Good",IF(Linked[[#This Row],[Credit Score]]<=799,"Very Good",IF(Linked[[#This Row],[Credit Score]]>=800,"Excellent"))))) -> Good | T20: 120819
A21: CUST0109 | B21: ACC00362 | C21: Emily Scott | D21: Female | E21: 29 | F21: Millennials | G21: North | H21: Engineer | I21: 44077 | J21: 2020 | K21: 2167 days | L21: 131785 | M21: Medium | N21: Corporate | O21: CreditCard | P21: 43869 | Q21: 207574 | R21: 803 | S21: =IF(Linked[[#This Row],[Credit Score]]<=579,"Poor",IF(Linked[[#This Row],[Credit Score]]<=669,"Fair",IF(Linked[[#This Row],[Credit Score]]<=739,"Good",IF(Linked[[#This Row],[Credit Score]]<=799,"Very Good",IF(Linked[[#This Row],[Credit Score]]>=800,"Excellent"))))) -> Excellent | T21: 0
A22: CUST0007 | B22: ACC00154 | C22: Tyler Fischer | D22: Male | E22: 42 | F22: Millennials | G22: North | H22: Engineer | I22: 43026 | J22: 2017 | K22: 3218 days | L22: 87364 | M22: Medium | N22: Corporate | O22: CreditCard | P22: 44895 | Q22: 439529 | R22: 587 | S22: =IF(Linked[[#This Row],[Credit Score]]<=579,"Poor",IF(Linked[[#This Row],[Credit Score]]<=669,"Fair",IF(Linked[[#This Row],[Credit Score]]<=739,"Good",IF(Linked[[#This Row],[Credit Score]]<=799,"Very Good",IF(Linked[[#This Row],[Credit Score]]>=800,"Excellent"))))) -> Fair | T22: 0
A23: CUST0076 | B23: ACC00008 | C23: Pamela Johnson | D23: Female | E23: 70 | F23: Boomers | G23: West | H23: Trader | I23: 42917 | J23: 2017 | K23: 3327 days | L23: 172826 | M23: High | N23: Retail | O23: Checking | P23: 45487 | Q23: 180903 | R23: 339 | S23: =IF(Linked[[#This Row],[Credit Score]]<=579,"Poor",IF(Linked[[#This Row],[Credit Score]]<=669,"Fair",IF(Linked[[#This Row],[Credit Score]]<=739,"Good",IF(Linked[[#This Row],[Credit Score]]<=799,"Very Good",IF(Linked[[#This Row],[Credit Score]]>=800,"Excellent"))))) -> Poor | T23: 0
A24: CUST0076 | B24: ACC00238 | C24: Pamela Johnson | D24: Female | E24: 70 | F24: Boomers | G24: West | H24: Trader | I24: 42917 | J24: 2017 | K24: 3327 days | L24: 172826 | M24: High | N24: Retail | O24: Checking | P24: 42353 | Q24: 249664 | R24: 536 | S24: =IF(Linked[[#This Row],[Credit Score]]<=579,"Poor",IF(Linked[[#This Row],[Credit Score]]<=669,"Fair",IF(Linked[[#This Row],[Credit Score]]<=739,"Good",IF(Linked[[#This Row],[Credit Score]]<=799,"Very Good",IF(Linked[[#This Row],[Credit Score]]>=800,"Excellent"))))) -> Poor | T24: 0
A25: CUST0076 | B25: ACC00411 | C25: Pamela Johnson | D25: Female | E25: 70 | F25: Boomers | G25: West | H25: Trader | I25: 42917 | J25: 2017 | K25: 3327 days | L25: 172826 | M25: High | N25: Retail | O25: Checking | P25: 44267 | Q25: 112701 | R25: 540 | S25: =IF(Linked[[#This Row],[Credit Score]]<=579,"Poor",IF(Linked[[#This Row],[Credit Score]]<=669,"Fair",IF(Linked[[#This Row],[Credit Score]]<=739,"Good",IF(Linked[[#This Row],[Credit Score]]<=799,"Very Good",IF(Linked[[#This Row],[Credit Score]]>=800,"Excellent"))))) -> Poor | T25: 0
A26: CUST0008 | B26: ACC00305 | C26: William Horton | D26: Male | E26: 59 | F26: Gen X | G26: North | H26: Engineer | I26: 45448 | J26: 2024 | K26: 796 days | L26: 144988 | M26: High | N26: Retail | O26: CreditCard | P26: 44584 | Q26: 389763 | R26: 444 | S26: =IF(Linked[[#This Row],[Credit Score]]<=579,"Poor",IF(Linked[[#This Row],[Credit Score]]<=669,"Fair",IF(Linked[[#This Row],[Credit Score]]<=739,"Good",IF(Linked[[#This Row],[Credit Score]]<=799,"Very Good",IF(Linked[[#This Row],[Credit Score]]>=800,"Excellent"))))) -> Poor | T26: 0 | U26: Default
A27: CUST0008 | B27: ACC00340 | C27: William Horton | D27: Male | E27: 59 | F27: Gen X | G27: North | H27: Engineer | I27: 45448 | J27: 2024 | K27: 796 days | L27: 144988 | M27: High | N27: Retail | O27: CreditCard | P27: 44887 | Q27: 101158 | R27: 472 | S27: =IF(Linked[[#This Row],[Credit Score]]<=579,"Poor",IF(Linked[[#This Row],[Credit Score]]<=669,"Fair",IF(Linked[[#This Row],[Credit Score]]<=739,"Good",IF(Linked[[#This Row],[Credit Score]]<=799,"Very Good",IF(Linked[[#This Row],[Credit Score]]>=800,"Excellent"))))) -> Poor | T27: 0
A28: CUST0030 | B28: ACC00009 | C28: Angela Robinson | D28: Female | E28: 71 | F28: Boomers | G28: South | H28: Student | I28: 44109 | J28: 2020 | K28: 2135 days | L28: 165271 | M28: High | N28: Retail | O28: CreditCard | P28: 42340 | Q28: 174499 | R28: 517 | S28: =IF(Linked[[#This Row],[Credit Score]]<=579,"Poor",IF(Linked[[#This Row],[Credit Score]]<=669,"Fair",IF(Linked[[#This Row],[Credit Score]]<=739,"Good",IF(Linked[[#This Row],[Credit Score]]<=799,"Very Good",IF(Linked[[#This Row],[Credit Score]]>=800,"Excellent"))))) -> Poor | T28: 0
A29: CUST0314 | B29: ACC00010 | C29: Kenneth Vasquez | D29: Male | E29: 34 | F29: Millennials | G29: West | H29: Doctor | I29: 44714 | J29: 2022 | K29: 1530 days | L29: 145150 | M29: High | N29: Retail | O29: Loan | P29: 45493 | Q29: 487025 | R29: 381 | S29: =IF(Linked[[#This Row],[Credit Score]]<=579,"Poor",IF(Linked[[#This Row],[Credit Score]]<=669,"Fair",IF(Linked[[#This Row],[Credit Score]]<=739,"Good",IF(Linked[[#This Row],[Credit Score]]<=799,"Very Good",IF(Linked[[#This Row],[Credit Score]]>=800,"Excellent"))))) -> Poor | T29: 0
A30: CUST0314 | B30: ACC00176 | C30: Kenneth Vasquez | D30: Male | E30: 34 | F30: Millennials | G30: West | H30: Doctor | I30: 44714 | J30: 2022 | K30: 1530 days | L30: 145150 | M30: High | N30: Retail | O30: Savings | P30: 44383 | Q30: 36320 | R30: 810 | S30: =IF(Linked[[#This Row],[Credit Score]]<=579,"Poor",IF(Linked[[#This Row],[Credit Score]]<=669,"Fair",IF(Linked[[#This Row],[Credit Score]]<=739,"Good",IF(Linked[[#This Row],[Credit Score]]<=799,"Very Good",IF(Linked[[#This Row],[Credit Score]]>=800,"Excellent"))))) -> Excellent | T30: 0 | U30: Default
A31: CUST0314 | B31: ACC00430 | C31: Kenneth Vasquez | D31: Male | E31: 34 | F31: Millennials | G31: West | H31: Doctor | I31: 44714 | J31: 2022 | K31: 1530 days | L31: 145150 | M31: High | N31: Retail | O31: Checking | P31: 44014 | Q31: 379747 | R31: 316 | S31: =IF(Linked[[#This Row],[Credit Score]]<=579,"Poor",IF(Linked[[#This Row],[Credit Score]]<=669,"Fair",IF(Linked[[#This Row],[Credit Score]]<=739,"Good",IF(Linked[[#This Row],[Credit Score]]<=799,"Very Good",IF(Linked[[#This Row],[Credit Score]]>=800,"Excellent"))))) -> Poor | T31: 0
A32: CUST0486 | B32: ACC00011 | C32: Ronald Craig | D32: Female | E32: 55 | F32: Gen X | G32: East | H32: Retired | I32: 45621 | J32: 2024 | K32: 623 days | L32: 166470 | M32: High | N32: Retail | O32: CreditCard | P32: 45351 | Q32: 130299 | R32: 500 | S32: =IF(Linked[[#This Row],[Credit Score]]<=579,"Poor",IF(Linked[[#This Row],[Credit Score]]<=669,"Fair",IF(Linked[[#This Row],[Credit Score]]<=739,"Good",IF(Linked[[#This Row],[Credit Score]]<=799,"Very Good",IF(Linked[[#This Row],[Credit Score]]>=800,"Excellent"))))) -> Poor | T32: 0
A33: CUST0486 | B33: ACC00336 | C33: Ronald Craig | D33: Female | E33: 55 | F33: Gen X | G33: East | H33: Retired | I33: 45621 | J33: 2024 | K33: 623 days | L33: 166470 | M33: High | N33: Retail | O33: CreditCard | P33: 44222 | Q33: 427876 | R33: 496 | S33: =IF(Linked[[#This Row],[Credit Score]]<=579,"Poor",IF(Linked[[#This Row],[Credit Score]]<=669,"Fair",IF(Linked[[#This Row],[Credit Score]]<=739,"Good",IF(Linked[[#This Row],[Credit Score]]<=799,"Very Good",IF(Linked[[#This Row],[Credit Score]]>=800,"Excellent"))))) -> Poor | T33: 0
A34: CUST0486 | B34: ACC00393 | C34: Ronald Craig | D34: Female | E34: 55 | F34: Gen X | G34: East | H34: Retired | I34: 45621 | J34: 2024 | K34: 623 days | L34: 166470 | M34: High | N34: Retail | O34: CreditCard | P34: 43220 | Q34: 434825 | R34: 613 | S34: =IF(Linked[[#This Row],[Credit Score]]<=579,"Poor",IF(Linked[[#This Row],[Credit Score]]<=669,"Fair",IF(Linked[[#This Row],[Credit Score]]<=739,"Good",IF(Linked[[#This Row],[Credit Score]]<=799,"Very Good",IF(Linked[[#This Row],[Credit Score]]>=800,"Excellent"))))) -> Fair | T34: 0
A35: CUST0117 | B35: ACC00012 | C35: Heidi Sharp | D35: Male | E35: 65 | F35: Boomers | G35: North | H35: Student | I35: 45706 | J35: 2025 | K35: 538 days | L35: 94553 | M35: Medium | N35: Retail | O35: Checking | P35: 44010 | Q35: 431722 | R35: 746 | S35: =IF(Linked[[#This Row],[Credit Score]]<=579,"Poor",IF(Linked[[#This Row],[Credit Score]]<=669,"Fair",IF(Linked[[#This Row],[Credit Score]]<=739,"Good",IF(Linked[[#This Row],[Credit Score]]<=799,"Very Good",IF(Linked[[#This Row],[Credit Score]]>=800,"Excellent"))))) -> Very Good | T35: 278365
A36: CUST0117 | B36: ACC00196 | C36: Heidi Sharp | D36: Male | E36: 65 | F36: Boomers | G36: North | H36: Student | I36: 45706 | J36: 2025 | K36: 538 days | L36: 94553 | M36: Medium | N36: Retail | O36: Savings | P36: 42688 | Q36: 422132 | R36: 650 | S36: =IF(Linked[[#This Row],[Credit Score]]<=579,"Poor",IF(Linked[[#This Row],[Credit Score]]<=669,"Fair",IF(Linked[[#This Row],[Credit Score]]<=739,"Good",IF(Linked[[#This Row],[Credit Score]]<=799,"Very Good",IF(Linked[[#This Row],[Credit Score]]>=800,"Excellent"))))) -> Fair | T36: 0
A37: CUST0117 | B37: ACC00478 | C37: Heidi Sharp | D37: Male | E37: 65 | F37: Boomers | G37: North | H37: Student | I37: 45706 | J37: 2025 | K37: 538 days | L37: 94553 | M37: Medium | N37: Retail | O37: CreditCard | P37: 42968 | Q37: 102476 | R37: 816 | S37: =IF(Linked[[#This Row],[Credit Score]]<=579,"Poor",IF(Linked[[#This Row],[Credit Score]]<=669,"Fair",IF(Linked[[#This Row],[Credit Score]]<=739,"Good",IF(Linked[[#This Row],[Credit Score]]<=799,"Very Good",IF(Linked[[#This Row],[Credit Score]]>=800,"Excellent"))))) -> Excellent | T37: 0
A38: CUST0012 | B38: ACC00355 | C38: Michael Richard | D38: Male | E38: 57 | F38: Gen X | G38: West | H38: Trader | I38: 45280 | J38: 2023 | K38: 964 days | L38: 144343 | M38: High | N38: Corporate | O38: Savings | P38: 43741 | Q38: 166782 | R38: 746 | S38: =IF(Linked[[#This Row],[Credit Score]]<=579,"Poor",IF(Linked[[#This Row],[Credit Score]]<=669,"Fair",IF(Linked[[#This Row],[Credit Score]]<=739,"Good",IF(Linked[[#This Row],[Credit Score]]<=799,"Very Good",IF(Linked[[#This Row],[Credit Score]]>=800,"Excellent"))))) -> Very Good | T38: 0
A39: CUST0415 | B39: ACC00013 | C39: Kyle Rodriguez | D39: Male | E39: 45 | F39: Gen X | G39: South | H39: Retired | I39: 45884 | J39: 2025 | K39: 360 days | L39: 145932 | M39: High | N39: Corporate | O39: Checking | P39: 45860 | Q39: 5668 | R39: 727 | S39: =IF(Linked[[#This Row],[Credit Score]]<=579,"Poor",IF(Linked[[#This Row],[Credit Score]]<=669,"Fair",IF(Linked[[#This Row],[Credit Score]]<=739,"Good",IF(Linked[[#This Row],[Credit Score]]<=799,"Very Good",IF(Linked[[#This Row],[Credit Score]]>=800,"Excellent"))))) -> Good | T39: 0 | U39: Approved
A40: CUST0356 | B40: ACC00014 | C40: Tyler Harris | D40: Male | E40: 67 | F40: Boomers | G40: West | H40: Banker | I40: 43374 | J40: 2018 | K40: 2870 days | L40: 134994 | M40: Medium | N40: Corporate | O40: Checking | P40: 44587 | Q40: 222542 | R40: 337 | S40: =IF(Linked[[#This Row],[Credit Score]]<=579,"Poor",IF(Linked[[#This Row],[Credit Score]]<=669,"Fair",IF(Linked[[#This Row],[Credit Score]]<=739,"Good",IF(Linked[[#This Row],[Credit Score]]<=799,"Very Good",IF(Linked[[#This Row],[Credit Score]]>=800,"Excellent"))))) -> Poor | T40: 18569
...

Sheet Dashboard

Sheet Pivot Table
B2: Count of Account | C2: Average of Credit Score | D2: Average of Balance
B3: 800 | C3: 579.52625 | D3: 265426.42 | G3: Key Performance Indicators
H4: Total | K4: Average Balance by Customer Segment
A5: Count of Account type by users | G5: AVG loan Amount | K5: Row Labels | L5: Average of Balance
A6: Row Labels | B6: Count of CustomerID | G6: No of Accounts | H6: =GETPIVOTDATA("Count of Account",$B$2) -> 800 | K6: Private | L6: 275113.66
A7: Savings | B7: 303 | G7: AVG balance | H7: =GETPIVOTDATA("Average of Balance",$B$2) -> 265426.42 | K7: Retail | L7: 267102.03
A8: Checking | B8: 246 | G8: AVG Credit Score | H8: =GETPIVOTDATA("Average of Credit Score",$B$2) -> 579.52625 | K8: Corporate | L8: 259460.32
A9: CreditCard | B9: 169 | K9: Grand Total | L9: 265426.42
A10: Loan | B10: 82
A11: Grand Total | B11: 800
A12: Average Credit Score Of Each accoun type | D12: Average Blance of Each Account Type | G12: Count of Loan Status | J12: count of Accounts By Region
A13: Row Labels | B13: Average of Credit Score | C13: Credit score Bracket | D13: Row Labels | E13: Average of Balance | G13: Row Labels | H13: Average of Credit Score | J13: Row Labels | K13: Count of AccountID | M13: Row Labels | N13: Average of Balance
A14: Checking | B14: 578.67073 | C14: ='Customers Account'!Y12 -> 0 | D14: Checking | E14: 275053.37 | G14: Approved | H14: 580.50877 | J14: South | K14: 235 | M14: Boomers | N14: 264878.39
A15: CreditCard | B15: 574.92899 | C15: ='Customers Account'!Y15 -> 0 | D15: CreditCard | E15: 257636.54 | G15: Rejected | H15: 591.81159 | J15: East | K15: 204 | M15: Gen X | N15: 247707.3
A16: Loan | B16: 564 | C16: ='Customers Account'!Y14 -> 0 | D16: Loan | E16: 290089.96 | G16: Grand Total | H16: 586.69841 | J16: North | K16: 193 | M16: Gen z | N16: 267779.71
A17: Savings | B17: 586.9868 | C17: ='Customers Account'!Y13 -> 0 | D17: Savings | E17: 255280.7 | J17: West | K17: 168 | M17: Millennials | N17: 282099.39
A18: Grand Total | B18: 579.52625 | C18: ='Customers Account'!Y10 -> 0 | D18: Grand Total | E18: 265426.42 | J18: Grand Total | K18: 800 | M18: Grand Total | N18: 265426.42
A20: Count of account type by age bracket
A21: Count of AccountID | B21: Column Labels | H21: Average credit score of Loan Status | K21: Average Yealy Balance
A22: Row Labels | B22: Boomers | C22: Gen X | D22: Gen z | E22: Millennials | F22: Grand Total | H22: Row Labels | I22: Average of Credit Score | K22: Row Labels | L22: Average of Balance
A23: Checking | B23: 49 | C23: 73 | D23: 38 | E23: 86 | F23: 246 | H23: Approved | I23: 580.50877 | K23: 2015 | L23: 265345.57
A24: CreditCard | B24: 41 | C24: 56 | D24: 30 | E24: 42 | F24: 169 | H24: Default | I24: 574.95833 | K24: 2016 | L24: 303577.76
A25: Loan | B25: 15 | C25: 20 | D25: 16 | E25: 31 | F25: 82 | H25: Rejected | I25: 591.81159 | K25: 2017 | L25: 259810.36
A26: Savings | B26: 70 | C26: 90 | D26: 63 | E26: 80 | F26: 303 | H26: (blank) | I26: 578.43291 | K26: 2018 | L26: 240614.63
A27: Grand Total | B27: 175 | C27: 239 | D27: 147 | E27: 239 | F27: 800 | H27: Grand Total | I27: 579.52625 | K27: 2019 | L27: 254128.83
K28: 2020 | L28: 259193.11
K29: 2021 | L29: 285277.08
K30: 2022 | L30: 285062.26
K31: 2023 | L31: 262055.24
K32: 2024 | L32: 243471.72
K33: 2025 | L33: 281619.89
K34: Grand Total | L34: 265426.42

Sheet Accounts
A1: AccountID | B1: CustomerID | C1: Account_Type | D1: Open_Date | E1: Balance | F1: Credit_Score | G1: Loan_Amount | H1: Loan_Status
A2: ACC00001 | B2: CUST0305 | C2: Checking | D2: 43258 | E2: 363265 | F2: 698 | G2: 0
A3: ACC00002 | B3: CUST0319 | C3: Savings | D3: 45670 | E3: 282169 | F3: 405 | G3: 0
A4: ACC00003 | B4: CUST0366 | C4: Savings | D4: 43852 | E4: 397674 | F4: 570 | G4: 0
A5: ACC00004 | B5: CUST0211 | C5: Savings | D5: 44837 | E5: 63610 | F5: 802 | G5: 401875 | H5: Rejected
A6: ACC00005 | B6: CUST0406 | C6: Savings | D6: 44039 | E6: 70843 | F6: 824 | G6: 458505
A7: ACC00006 | B7: CUST0152 | C7: Checking | D7: 44185 | E7: 107237 | F7: 331 | G7: 163666
A8: ACC00007 | B8: CUST0109 | C8: CreditCard | D8: 44160 | E8: 477177 | F8: 692 | G8: 120819
A9: ACC00008 | B9: CUST0076 | C9: Checking | D9: 45487 | E9: 180903 | F9: 339 | G9: 0
A10: ACC00009 | B10: CUST0030 | C10: CreditCard | D10: 42340 | E10: 174499 | F10: 517 | G10: 0
A11: ACC00010 | B11: CUST0314 | C11: Loan | D11: 45493 | E11: 487025 | F11: 381 | G11: 0
A12: ACC00011 | B12: CUST0486 | C12: CreditCard | D12: 45351 | E12: 130299 | F12: 500 | G12: 0
A13: ACC00012 | B13: CUST0117 | C13: Checking | D13: 44010 | E13: 431722 | F13: 746 | G13: 278365
A14: ACC00013 | B14: CUST0415 | C14: Checking | D14: 45860 | E14: 5668 | F14: 727 | G14: 0 | H14: Approved
A15: ACC00014 | B15: CUST0356 | C15: Checking | D15: 44587 | E15: 222542 | F15: 337 | G15: 18569
A16: ACC00015 | B16: CUST0192 | C16: Savings | D16: 45438 | E16: 178267 | F16: 510 | G16: 0
A17: ACC00016 | B17: CUST0019 | C17: Savings | D17: 43064 | E17: 335377 | F17: 743 | G17: 0
A18: ACC00017 | B18: CUST0432 | C18: Loan | D18: 44333 | E18: 155489 | F18: 626 | G18: 207630
A19: ACC00018 | B19: CUST0173 | C19: CreditCard | D19: 44007 | E19: 344126 | F19: 526 | G19: 0
A20: ACC00019 | B20: CUST0228 | C20: Savings | D20: 44694 | E20: 106133 | F20: 347 | G20: 0 | H20: Rejected
A21: ACC00020 | B21: CUST0350 | C21: Checking | D21: 43335 | E21: 272895 | F21: 317 | G21: 0
A22: ACC00021 | B22: CUST0183 | C22: CreditCard | D22: 43980 | E22: 308362 | F22: 738 | G22: 0
A23: ACC00022 | B23: CUST0113 | C23: Savings | D23: 45635 | E23: 388793 | F23: 486 | G23: 258078
A24: ACC00023 | B24: CUST0183 | C24: Savings | D24: 45186 | E24: 269496 | F24: 644 | G24: 0 | H24: Default
A25: ACC00024 | B25: CUST0481 | C25: CreditCard | D25: 43146 | E25: 210124 | F25: 523 | G25: 0
A26: ACC00025 | B26: CUST0146 | C26: Checking | D26: 42535 | E26: 88835 | F26: 787 | G26: 485443
A27: ACC00026 | B27: CUST0319 | C27: Savings | D27: 43851 | E27: 97493 | F27: 528 | G27: 0
A28: ACC00027 | B28: CUST0116 | C28: Checking | D28: 45203 | E28: 291071 | F28: 689 | G28: 196007
A29: ACC00028 | B29: CUST0113 | C29: CreditCard | D29: 43189 | E29: 172166 | F29: 487 | G29: 0 | H29: Default
A30: ACC00029 | B30: CUST0251 | C30: Checking | D30: 43955 | E30: 101948 | F30: 569 | G30: 335724
A31: ACC00030 | B31: CUST0476 | C31: Savings | D31: 43461 | E31: 185194 | F31: 609 | G31: 0
A32: ACC00031 | B32: CUST0251 | C32: Savings | D32: 44092 | E32: 29493 | F32: 431 | G32: 0
A33: ACC00032 | B33: CUST0303 | C33: Checking | D33: 45191 | E33: 485463 | F33: 371 | G33: 0
A34: ACC00033 | B34: CUST0459 | C34: Checking | D34: 45495 | E34: 466755 | F34: 486 | G34: 0 | H34: Default
A35: ACC00034 | B35: CUST0313 | C35: CreditCard | D35: 42433 | E35: 293851 | F35: 785 | G35: 0
A36: ACC00035 | B36: CUST0118 | C36: Savings | D36: 43495 | E36: 199886 | F36: 490 | G36: 0
A37: ACC00036 | B37: CUST0301 | C37: CreditCard | D37: 44385 | E37: 138368 | F37: 721 | G37: 0
A38: ACC00037 | B38: CUST0161 | C38: Savings | D38: 44430 | E38: 156470 | F38: 419 | G38: 0
A39: ACC00038 | B39: CUST0401 | C39: Savings | D39: 43619 | E39: 297986 | F39: 519 | G39: 5654
A40: ACC00039 | B40: CUST0198 | C40: Savings | D40: 45596 | E40: 13261 | F40: 352 | G40: 59633
...

Sheet MetroBankAccounts
A1: AccountID | B1: CustomerID | C1: Account_Type | D1: Open_Date | E1: Balance | F1: Credit_Score | G1: Loan_Amount | H1: Loan_Status
A2: ACC00001 | B2: CUST0305 | C2: Checking | D2: 43258 | E2: 363265 | F2: 698 | G2: 0
A3: ACC00002 | B3: CUST0319 | C3: Savings | D3: 45670 | E3: 282169 | F3: 405 | G3: 0
A4: ACC00003 | B4: CUST0366 | C4: Savings | D4: 43852 | E4: 397674 | F4: 570 | G4: 0
A5: ACC00004 | B5: CUST0211 | C5: Savings | D5: 44837 | E5: 63610 | F5: 802 | G5: 401875 | H5: Rejected
A6: ACC00005 | B6: CUST0406 | C6: Savings | D6: 44039 | E6: 70843 | F6: 824 | G6: 458505
A7: ACC00006 | B7: CUST0152 | C7: Checking | D7: 44185 | E7: 107237 | F7: 331 | G7: 163666
A8: ACC00007 | B8: CUST0109 | C8: CreditCard | D8: 44160 | E8: 477177 | F8: 692 | G8: 120819
A9: ACC00008 | B9: CUST0076 | C9: Checking | D9: 45487 | E9: 180903 | F9: 339 | G9: 0
A10: ACC00009 | B10: CUST0030 | C10: CreditCard | D10: 42340 | E10: 174499 | F10: 517 | G10: 0
A11: ACC00010 | B11: CUST0314 | C11: Loan | D11: 45493 | E11: 487025 | F11: 381 | G11: 0
A12: ACC00011 | B12: CUST0486 | C12: CreditCard | D12: 45351 | E12: 130299 | F12: 500 | G12: 0
A13: ACC00012 | B13: CUST0117 | C13: Checking | D13: 44010 | E13: 431722 | F13: 746 | G13: 278365
A14: ACC00013 | B14: CUST0415 | C14: Checking | D14: 45860 | E14: 5668 | F14: 727 | G14: 0 | H14: Approved
A15: ACC00014 | B15: CUST0356 | C15: Checking | D15: 44587 | E15: 222542 | F15: 337 | G15: 18569
A16: ACC00015 | B16: CUST0192 | C16: Savings | D16: 45438 | E16: 178267 | F16: 510 | G16: 0
A17: ACC00016 | B17: CUST0019 | C17: Savings | D17: 43064 | E17: 335377 | F17: 743 | G17: 0
A18: ACC00017 | B18: CUST0432 | C18: Loan | D18: 44333 | E18: 155489 | F18: 626 | G18: 207630
A19: ACC00018 | B19: CUST0173 | C19: CreditCard | D19: 44007 | E19: 344126 | F19: 526 | G19: 0
A20: ACC00019 | B20: CUST0228 | C20: Savings | D20: 44694 | E20: 106133 | F20: 347 | G20: 0 | H20: Rejected
A21: ACC00020 | B21: CUST0350 | C21: Checking | D21: 43335 | E21: 272895 | F21: 317 | G21: 0
A22: ACC00021 | B22: CUST0183 | C22: CreditCard | D22: 43980 | E22: 308362 | F22: 738 | G22: 0
A23: ACC00022 | B23: CUST0113 | C23: Savings | D23: 45635 | E23: 388793 | F23: 486 | G23: 258078
A24: ACC00023 | B24: CUST0183 | C24: Savings | D24: 45186 | E24: 269496 | F24: 644 | G24: 0 | H24: Default
A25: ACC00024 | B25: CUST0481 | C25: CreditCard | D25: 43146 | E25: 210124 | F25: 523 | G25: 0
A26: ACC00025 | B26: CUST0146 | C26: Checking | D26: 42535 | E26: 88835 | F26: 787 | G26: 485443
A27: ACC00026 | B27: CUST0319 | C27: Savings | D27: 43851 | E27: 97493 | F27: 528 | G27: 0
A28: ACC00027 | B28: CUST0116 | C28: Checking | D28: 45203 | E28: 291071 | F28: 689 | G28: 196007
A29: ACC00028 | B29: CUST0113 | C29: CreditCard | D29: 43189 | E29: 172166 | F29: 487 | G29: 0 | H29: Default
A30: ACC00029 | B30: CUST0251 | C30: Checking | D30: 43955 | E30: 101948 | F30: 569 | G30: 335724
A31: ACC00030 | B31: CUST0476 | C31: Savings | D31: 43461 | E31: 185194 | F31: 609 | G31: 0
A32: ACC00031 | B32: CUST0251 | C32: Savings | D32: 44092 | E32: 29493 | F32: 431 | G32: 0
A33: ACC00032 | B33: CUST0303 | C33: Checking | D33: 45191 | E33: 485463 | F33: 371 | G33: 0
A34: ACC00033 | B34: CUST0459 | C34: Checking | D34: 45495 | E34: 466755 | F34: 486 | G34: 0 | H34: Default
A35: ACC00034 | B35: CUST0313 | C35: CreditCard | D35: 42433 | E35: 293851 | F35: 785 | G35: 0
A36: ACC00035 | B36: CUST0118 | C36: Savings | D36: 43495 | E36: 199886 | F36: 490 | G36: 0
A37: ACC00036 | B37: CUST0301 | C37: CreditCard | D37: 44385 | E37: 138368 | F37: 721 | G37: 0
A38: ACC00037 | B38: CUST0161 | C38: Savings | D38: 44430 | E38: 156470 | F38: 419 | G38: 0
A39: ACC00038 | B39: CUST0401 | C39: Savings | D39: 43619 | E39: 297986 | F39: 519 | G39: 5654
A40: ACC00039 | B40: CUST0198 | C40: Savings | D40: 45596 | E40: 13261 | F40: 352 | G40: 59633
...
